Workbook

Sheet AUG - 2026 month generation
A1: Plant Name : 1 MWp New Solar Power Plant | D1: AUG- 2026 Generation report
A2: Date | B2: Insolation for the day(POA) | C2: Loss of Insolation for the day due to grid failure | D2: Insolation for the day with grid outage period taken out | E2: Deemed Generation | F2: Meter Reading In HT Yard (Billing Meter ) | G2: Total Export for the day (KWH) | H2: Total Generation(including deemed generation) | I2: Total Generation in Inverters | J2: PR(Actual)=PRday considering "E", grid outage & load shedding | K2: Guaranteed PR | L2: CUF | M2: Plant Generation Time | N2: Plant UP time | O2: Plant down time | P2: Grid outage loss time | Q2: Weather | R2: Ambient Temperature© | S2: Surface Temperature© | T2: PM & Module cleaning deatiles (Statues) | U2: Breakdown | V2: Remark
B3: Wh/m2 | C3: Wh/m2 | D3: Wh/m2 | E3: kWh | H3: kwh | I3: KWh | J3: (%) | K3: (%) | L3: (%) | M3: min | N3: (%) | O3: min | P3: min
A4: 46235 | D4: =B4-C4 -> 0 | H4: =SUM(E4,G4) -> 0 | J4: =(H4)/(B4*1) -> #DIV/0! | L4: =H4/24/(1*1000) -> 0 | N4: =(M4-O4)/M4 -> #DIV/0!
A5: 46236 | D5: =B5-C5 -> 0 | H5: =SUM(E5,G5) -> 0 | J5: =(H5)/(B5*1) -> #DIV/0! | L5: =H5/24/(1*1000) -> 0 | N5: =(M5-O5)/M5 -> #DIV/0!
A6: 46237 | D6: =B6-C6 -> 0 | H6: =SUM(E6,G6) -> 0 | J6: =(H6)/(B6*1) -> #DIV/0! | L6: =H6/24/(1*1000) -> 0 | N6: =(M6-O6)/M6 -> #DIV/0!
A7: 46238 | B7: 4467 | C7: 0 | D7: =B7-C7 -> 4467 | E7: 0 | F7: 0 | G7: 3118 | H7: =SUM(E7,G7) -> 3118 | I7: 3118 | J7: =(H7)/(B7*1) -> 0.69800761 | K7: 0.7426 | L7: =H7/24/(1*1000) -> 0.12991667 | M7: 750 | N7: =(M7-O7)/M7 -> 1 | O7: 0 | P7: 0 | Q7: Climate Varation | S7: 27 | V7: Three Inverter Running In Tempoary Cable
A8: 46239 | D8: =B8-C8 -> 0 | H8: =SUM(E8,G8) -> 0 | J8: =(H8)/(B8*1) -> #DIV/0! | L8: =H8/24/(1*1000) -> 0 | N8: =(M8-O8)/M8 -> #DIV/0! | AE8: g
A9: 46240 | D9: =B9-C9 -> 0 | H9: =SUM(E9,G9) -> 0 | J9: =(H9)/(B9*1) -> #DIV/0! | L9: =H9/24/(1*1000) -> 0 | N9: =(M9-O9)/M9 -> #DIV/0!
A10: 46241 | D10: =B10-C10 -> 0 | H10: =SUM(E10,G10) -> 0 | J10: =(H10)/(B10*1) -> #DIV/0! | L10: =H10/24/(1*1000) -> 0 | N10: =(M10-O10)/M10 -> #DIV/0!
A11: 46242 | D11: =B11-C11 -> 0 | H11: =SUM(E11,G11) -> 0 | J11: =(H11)/(B11*1) -> #DIV/0! | L11: =H11/24/(1*1000) -> 0 | N11: =(M11-O11)/M11 -> #DIV/0!
A12: 46243 | D12: =B12-C12 -> 0 | H12: =SUM(E12,G12) -> 0 | J12: =(H12)/(B12*1) -> #DIV/0! | L12: =H12/24/(1*1000) -> 0 | N12: =(M12-O12)/M12 -> #DIV/0!
A13: 46244 | D13: =B13-C13 -> 0 | H13: =SUM(E13,G13) -> 0 | J13: =(H13)/(B13*1) -> #DIV/0! | L13: =H13/24/(1*1000) -> 0 | N13: =(M13-O13)/M13 -> #DIV/0!
A14: 46245 | D14: =B14-C14 -> 0 | H14: =SUM(E14,G14) -> 0 | J14: =(H14)/(B14*1) -> #DIV/0! | L14: =H14/24/(1*1000) -> 0 | N14: =(M14-O14)/M14 -> #DIV/0!
A15: 46246 | D15: =B15-C15 -> 0 | H15: =SUM(E15,G15) -> 0 | I15: =SUM(F15,H15) -> 0 | J15: =(H15)/(B15*1) -> #DIV/0! | L15: =H15/24/(1*1000) -> 0 | N15: =(M15-O15)/M15 -> #DIV/0!
A16: 46247 | D16: =B16-C16 -> 0 | H16: =SUM(E16,G16) -> 0 | J16: =(H16)/(B16*1) -> #DIV/0! | L16: =H16/24/(1*1000) -> 0 | N16: =(M16-O16)/M16 -> #DIV/0!
A17: 46248 | D17: =B17-C17 -> 0 | H17: =SUM(E17,G17) -> 0 | J17: =(H17)/(B17*1) -> #DIV/0! | L17: =H17/24/(1*1000) -> 0 | N17: =(M17-O17)/M17 -> #DIV/0!
A18: 46249 | B18: 5213 | C18: 500 | D18: =B18-C18 -> 4713 | E18: 350 | F18: 0 | G18: 3197 | H18: =SUM(E18,G18) -> 3547 | I18: 3197 | J18: =(H18)/(B18*1) -> 0.68041435 | K18: 0.7446 | L18: =H18/24/(1*1000) -> 0.14779167 | M18: 750 | N18: =(M18-O18)/M18 -> 0.91333333 | O18: 65 | P18: 65 | Q18: Climate Varation | S18: 21 | V18: Climate Varation
A19: 46250 | D19: =B19-C19 -> 0 | H19: =SUM(E19,G19) -> 0 | J19: =(H19)/(B19*1) -> #DIV/0! | L19: =H19/24/(1*1000) -> 0 | N19: =(M19-O19)/M19 -> #DIV/0!
A20: 46251 | D20: =B20-C20 -> 0 | H20: =SUM(E20,G20) -> 0 | J20: =(H20)/(B20*1) -> #DIV/0! | L20: =H20/24/(1*1000) -> 0 | N20: =(M20-O20)/M20 -> #DIV/0!
A21: 46252 | B21: 5400 | C21: 700 | D21: =B21-C21 -> 4700 | E21: 400 | F21: 0 | G21: 3715 | H21: =SUM(E21,G21) -> 4115 | I21: 3715 | J21: =(H21)/(B21*1) -> 0.76203704 | K21: 0.7443 | L21: =H21/24/(1*1000) -> 0.17145833 | M21: 750 | N21: =(M21-O21)/M21 -> 0.904 | O21: 72 | P21: 72 | Q21: Climate Varation | S21: 29 | V21: Climate Varation
A22: 46253 | D22: =B22-C22 -> 0 | H22: =SUM(E22,G22) -> 0 | J22: =(H22)/(B22*1) -> #DIV/0! | L22: =H22/24/(1*1000) -> 0 | N22: =(M22-O22)/M22 -> #DIV/0!
A23: 46254 | D23: =B23-C23 -> 0 | H23: =SUM(E23,G23) -> 0 | J23: =(H23)/(B23*1) -> #DIV/0! | L23: =H23/24/(1*1000) -> 0 | N23: =(M23-O23)/M23 -> #DIV/0!
A24: 46255 | D24: =B24-C24 -> 0 | H24: =SUM(E24,G24) -> 0 | J24: =(H24)/(B24*1) -> #DIV/0! | L24: =H24/24/(1*1000) -> 0 | N24: =(M24-O24)/M24 -> #DIV/0!
A25: 46256 | D25: =B25-C25 -> 0 | H25: =SUM(E25,G25) -> 0 | J25: =(H25)/(B25*1) -> #DIV/0! | L25: =H25/24/(1*1000) -> 0 | N25: =(M25-O25)/M25 -> #DIV/0!
A26: 46257 | D26: =B26-C26 -> 0 | H26: =SUM(E26,G26) -> 0 | J26: =(H26)/(B26*1) -> #DIV/0! | L26: =H26/24/(1*1000) -> 0 | N26: =(M26-O26)/M26 -> #DIV/0!
A27: 46258 | D27: =B27-C27 -> 0 | H27: =SUM(E27,G27) -> 0 | J27: =(H27)/(B27*1) -> #DIV/0! | L27: =H27/24/(1*1000) -> 0 | N27: =(M27-O27)/M27 -> #DIV/0!
A28: 46259 | D28: =B28-C28 -> 0 | H28: =SUM(E28,G28) -> 0 | J28: =(H28)/(B28*1) -> #DIV/0! | L28: =H28/24/(1*1000) -> 0 | N28: =(M28-O28)/M28 -> #DIV/0!
A29: 46260 | D29: =B29-C29 -> 0 | H29: =SUM(E29,G29) -> 0 | J29: =(H29)/(B29*1) -> #DIV/0! | L29: =H29/24/(1*1000) -> 0 | N29: =(M29-O29)/M29 -> #DIV/0!
A30: 46261 | D30: =B30-C30 -> 0 | H30: =SUM(E30,G30) -> 0 | J30: =(H30)/(B30*1) -> #DIV/0! | L30: =H30/24/(1*1000) -> 0 | N30: =(M30-O30)/M30 -> #DIV/0!
A31: 46262 | D31: =B31-C31 -> 0 | H31: =SUM(E31,G31) -> 0 | J31: =(H31)/(B31*1) -> #DIV/0! | L31: =H31/24/(1*1000) -> 0 | N31: =(M31-O31)/M31 -> #DIV/0!
A32: 46263 | D32: =B32-C32 -> 0 | H32: =SUM(E32,G32) -> 0 | J32: =(H32)/(B32*1) -> #DIV/0! | L32: =H32/24/(1*1000) -> 0 | N32: =(M32-O32)/M32 -> #DIV/0!
A33: 46264 | D33: =B33-C33 -> 0 | H33: =SUM(E33,G33) -> 0 | J33: =(H33)/(B33*1) -> #DIV/0! | L33: =H33/24/(1*1000) -> 0 | N33: =(M33-O33)/M33 -> #DIV/0!
A34: 46265 | D34: =B34-C34 -> 0 | H34: =SUM(E34,G34) -> 0 | J34: =(H34)/(B34*1) -> #DIV/0! | L34: =H34/24/(1*1000) -> 0 | N34: =(M34-O34)/M34 -> #DIV/0!
A35: Total | B35: =SUM(B4:B34) -> 15080 | D35: =B35-C35 -> 15080 | G35: =SUM(G4:G34) -> 10030 | H35: =SUM(E35,G35) -> 10030 | I35: =SUM(I4:I34) -> 10030 | J35: =(H35)/(B35*2.9) -> 0.2293515 | L35: =H35/24/(2.9*1000) -> 0.1441092 | N35: =(M35-O35)/M35 -> #DIV/0!

Sheet PR Graph
A1: Plant | B1: 2.9 MWp RBA Textiles Kumppam
A2: DC Capacity | B2: 2.9 MWp
A3: Date | B3: Insolation -POA (Wh/m2) | C3: Generation | D3: Guaranteed PR | E3: Actual PR (contractual) | F3: Specific Yield (kWh/MWp)
A4: 42449 | B4: 7261.5 | C4: 12214 | E4: 0.71881266 | F4: =C4/$B$2 -> #VALUE!
A5: 42450 | B5: 7124.6 | C5: 11980.2 | E5: 0.71860085 | F5: =C5/$B$2 -> #VALUE!
A6: 42451 | B6: 7483.9 | C6: 12470.9 | E6: 0.71212128 | F6: =C6/$B$2 -> #VALUE!
A7: 42452 | B7: 6402.4 | C7: 10814.8 | E7: 0.72187139 | F7: =C7/$B$2 -> #VALUE!
A8: 42453 | B8: 6682.2 | C8: 11294.3 | E8: 0.72231061 | F8: =C8/$B$2 -> #VALUE!
A9: 42454 | B9: 6825.2 | C9: 11547.9 | E9: 0.72305573 | F9: =C9/$B$2 -> #VALUE!
A10: 42455 | B10: 6310.1 | C10: 10689.5 | E10: 0.72394453 | F10: =C10/$B$2 -> #VALUE!
A11: 42456 | B11: 6251.3 | C11: 10564.5 | E11: 0.72220875 | F11: =C11/$B$2 -> #VALUE!
A12: 42457 | B12: 6555.3 | C12: 11260.4 | E12: 0.73408338 | F12: =C12/$B$2 -> #VALUE!
A13: 42458 | B13: 6090.3 | C13: 10210.6 | E13: 0.71646787 | F13: =C13/$B$2 -> #VALUE!
A14: 42459 | B14: 5950.2 | C14: 10057.2 | E14: 0.72232004 | F14: =C14/$B$2 -> #VALUE!
A15: 42460 | B15: 5372.9 | C15: 9176.1 | E15: 0.72984985 | F15: =C15/$B$2 -> #VALUE!
A16: 42461 | B16: 0 | C16: 0 | E16: #VALUE! | F16: =C16/$B$2 -> #VALUE!
A17: 42462 | B17: 0 | C17: 0 | E17: #VALUE! | F17: =C17/$B$2 -> #VALUE!
A18: 42463 | B18: 0 | C18: 0 | E18: #VALUE! | F18: =C18/$B$2 -> #VALUE!
A19: 42464 | B19: 0 | C19: 0 | E19: #VALUE! | F19: =C19/$B$2 -> #VALUE!
A20: 42465 | B20: 6092.89 | C20: 5501.4 | E20: 0.77905201 | F20: =C20/$B$2 -> #VALUE!
A21: 42466 | B21: 0 | C21: 0 | E21: #VALUE! | F21: =C21/$B$2 -> #VALUE!
A22: 42467 | B22: 0 | C22: 0 | E22: #VALUE! | F22: =C22/$B$2 -> #VALUE!
A23: 42468 | B23: 0 | C23: 0 | E23: #VALUE! | F23: =C23/$B$2 -> #VALUE!
A24: 42469 | B24: 0 | C24: 0 | E24: #VALUE! | F24: =C24/$B$2 -> #VALUE!
A25: 42470 | B25: 0 | C25: 0 | E25: #VALUE! | F25: =C25/$B$2 -> #VALUE!
A26: 42471 | B26: 0 | C26: 0 | E26: #VALUE! | F26: =C26/$B$2 -> #VALUE!
A27: 42472 | B27: 0 | C27: 0 | E27: #VALUE! | F27: =C27/$B$2 -> #VALUE!
A28: 42473 | B28: 0 | C28: 0 | E28: #VALUE! | F28: =C28/$B$2 -> #VALUE!
A29: 42474 | B29: 0 | C29: 0 | E29: #VALUE! | F29: =C29/$B$2 -> #VALUE!
A30: 42475 | B30: 0 | C30: 0 | E30: #VALUE! | F30: =C30/$B$2 -> #VALUE!
A31: 42476 | B31: 6559.1 | C31: 10989.1 | E31: 0.71598185 | F31: =C31/$B$2 -> #VALUE!
A32: 42477 | B32: 576.3 | C32: 971.2 | E32: 0.72018521 | F32: =C32/$B$2 -> #VALUE!
A33: 42478 | B33: 4880.1 | C33: 8333 | E33: 0.72972093 | F33: =C33/$B$2 -> #VALUE!
A34: 42479 | B34: 7147 | C34: 12124.5 | E34: 0.72497695 | F34: =C34/$B$2 -> #VALUE!
A35: ='AUG - 2026 month generation'!A14 -> 46245 | B35: ='AUG - 2026 month generation'!D4 -> 0 | C35: ='AUG - 2026 month generation'!G4 -> 0 | D35: 0.78 | E35: ='AUG - 2026 month generation'!J4 -> #DIV/0! | F35: =C35/2900 -> 0
A36: ='AUG - 2026 month generation'!A5 -> 46236 | B36: ='AUG - 2026 month generation'!D5 -> 0 | C36: ='AUG - 2026 month generation'!G5 -> 0 | D36: 0.78 | E36: ='AUG - 2026 month generation'!J5 -> #DIV/0! | F36: =C36/2900 -> 0
A37: ='AUG - 2026 month generation'!A6 -> 46237 | B37: ='AUG - 2026 month generation'!D6 -> 0 | C37: ='AUG - 2026 month generation'!G6 -> 0 | D37: 0.78 | E37: ='AUG - 2026 month generation'!J6 -> #DIV/0! | F37: =C37/2900 -> 0
A38: ='AUG - 2026 month generation'!A7 -> 46238 | B38: ='AUG - 2026 month generation'!D7 -> 4467 | C38: ='AUG - 2026 month generation'!G7 -> 3118 | D38: 0.78 | E38: ='AUG - 2026 month generation'!J7 -> 0.69800761 | F38: =C38/2900 -> 1.0751724
A39: ='AUG - 2026 month generation'!A8 -> 46239 | B39: ='AUG - 2026 month generation'!D8 -> 0 | C39: ='AUG - 2026 month generation'!G8 -> 0 | D39: 0.78 | E39: ='AUG - 2026 month generation'!J8 -> #DIV/0! | F39: =C39/2900 -> 0
A40: ='AUG - 2026 month generation'!A9 -> 46240 | B40: ='AUG - 2026 month generation'!D9 -> 0 | C40: ='AUG - 2026 month generation'!G9 -> 0 | D40: 0.78 | E40: ='AUG - 2026 month generation'!J9 -> #DIV/0! | F40: =C40/2900 -> 0
...

Sheet Daily Energy
A1: 1 MWp Akshaya Solar Power Plant
A2: INV-NO | B2: DC capacity(KW) | C2: 46235 | D2: 46236 | E2: 46237 | F2: 46238 | G2: 46239 | H2: 46240 | I2: 46241 | J2: 46242 | K2: 46243 | L2: 46244 | M2: 46245 | N2: 46246 | O2: 46247 | P2: 46248 | Q2: 46249 | R2: 46250 | S2: 46251 | T2: 46252 | U2: 46253 | V2: 46254 | W2: 46255 | X2: 46256 | Y2: 46257 | Z2: 46258 | AA2: 46259 | AB2: 46260 | AC2: 46261 | AD2: 46262 | AE2: 46263 | AF2: 46264 | AG2: 46265
A3: INV-1 | B3: 127.53 | P3: 208 | Q3: 218 | T3: 178
A4: INV-2 | B4: 127.53 | P4: 248 | Q4: 248 | T4: 310
A5: INV-3 | B5: 127.53 | P5: 243 | Q5: 256 | T5: 300
A6: INV-4 | B6: 127.53 | P6: 213 | Q6: 235 | T6: 275
A7: INV-5 | B7: 127.53 | P7: 251 | Q7: 257 | T7: 311
A8: INV-6 | B8: 127.53 | P8: 237 | Q8: 244 | T8: 289
A9: INV-7 | B9: 137.34 | P9: 255 | Q9: 260 | T9: 315
A10: INV-8 | B10: 137.34 | P10: 231 | Q10: 236 | T10: 240
A11: INV-9 | B11: 137.34 | P11: 250 | Q11: 256 | T11: 305
A12: INV-10 | B12: 137.34 | P12: 260 | Q12: 240 | T12: 312
A13: INV-11 | B13: 137.34 | P13: 231 | Q13: 237 | T13: 280
A14: INV-12 | B14: 127.53 | P14: 252 | Q14: 260 | T14: 310
A15: INV-13 | B15: 127.53 | P15: 239 | Q15: 250 | T15: 290
A16: INV-14 | B16: 127.53
A17: INV-15 | B17: 127.53
A18: INV-16 | B18: 127.53
A19: INV-17 | B19: 127.53
A20: INV-18 | B20: 137.34
A21: INV-19 | B21: 137.34
A22: INV-20 | B22: 137.34
A23: INV-21 | B23: 137.34
A24: INV-22 | B24: 137.34

Sheet Daily SY
A1: RBA, Textiles
A2: INV No | B2: DC capacity(KW) | C2: ='Daily Energy'!C2 -> 46235 | D2: ='Daily Energy'!D2 -> 46236 | E2: ='Daily Energy'!E2 -> 46237 | F2: ='Daily Energy'!F2 -> 46238 | G2: ='Daily Energy'!G2 -> 46239 | H2: ='Daily Energy'!H2 -> 46240 | I2: ='Daily Energy'!I2 -> 46241 | J2: ='Daily Energy'!J2 -> 46242 | ... AG2: ='Daily Energy'!AG2 -> 46265
A3: INV-1 | B3: 127.53 | C3: 489 | D3: ='Daily Energy'!D4/'Daily Energy'!$B3 -> 0 | E3: ='Daily Energy'!E3/'Daily Energy'!$B3 -> 0 | F3: ='Daily Energy'!F3/'Daily Energy'!$B3 -> 0 | G3: ='Daily Energy'!G3/'Daily Energy'!$B3 -> 0 | H3: ='Daily Energy'!H3/'Daily Energy'!$B3 -> 0 | I3: ='Daily Energy'!I3/'Daily Energy'!$B3 -> 0 | J3: ='Daily Energy'!J3/'Daily Energy'!$B3 -> 0 | K3: ='Daily Energy'!K3/'Daily Energy'!$B3 -> 0 | L3: ='Daily Energy'!L3/'Daily Energy'!$B3 -> 0 | ... U3: ='Daily Energy'!U3/'Daily Energy'!$B3 -> 0 | V3: ='Daily Energy'!W3/'Daily Energy'!$B3 -> 0 | W3: ='Daily Energy'!X3/'Daily Energy'!$B3 -> 0 | X3: ='Daily Energy'!Z3/'Daily Energy'!$B3 -> 0 | Y3: ='Daily Energy'!#REF!/'Daily Energy'!$B3 -> #REF! | Z3: ='Daily Energy'!#REF!/'Daily Energy'!$B3 -> #REF! | AA3: ='Daily Energy'!AA3/'Daily Energy'!$B3 -> 0 | AB3: ='Daily Energy'!AB3/'Daily Energy'!$B3 -> 0 | AC3: ='Daily Energy'!AC3/'Daily Energy'!$B3 -> 0 | AD3: ='Daily Energy'!AD3/'Daily Energy'!$B3 -> 0 | AE3: ='Daily Energy'!AE3/'Daily Energy'!$B3 -> 0 | AF3: ='Daily Energy'!AF3/'Daily Energy'!$B3 -> 0 | AG3: ='Daily Energy'!AG3/'Daily Energy'!$B3 -> 0
A4: INV-2 | B4: 127.53 | C4: 495 | D4: ='Daily Energy'!D5/'Daily Energy'!$B4 -> 0 | E4: ='Daily Energy'!E4/'Daily Energy'!$B4 -> 0 | F4: ='Daily Energy'!F4/'Daily Energy'!$B4 -> 0 | G4: ='Daily Energy'!G4/'Daily Energy'!$B4 -> 0 | H4: ='Daily Energy'!H4/'Daily Energy'!$B4 -> 0 | I4: ='Daily Energy'!I4/'Daily Energy'!$B4 -> 0 | J4: ='Daily Energy'!J4/'Daily Energy'!$B4 -> 0 | K4: ='Daily Energy'!K4/'Daily Energy'!$B4 -> 0 | L4: ='Daily Energy'!L4/'Daily Energy'!$B4 -> 0 | ... U4: ='Daily Energy'!U4/'Daily Energy'!$B4 -> 0 | V4: ='Daily Energy'!W4/'Daily Energy'!$B4 -> 0 | W4: ='Daily Energy'!X4/'Daily Energy'!$B4 -> 0 | X4: ='Daily Energy'!Z4/'Daily Energy'!$B4 -> 0 | Y4: ='Daily Energy'!#REF!/'Daily Energy'!$B4 -> #REF! | Z4: ='Daily Energy'!#REF!/'Daily Energy'!$B4 -> #REF! | AA4: ='Daily Energy'!AA4/'Daily Energy'!$B4 -> 0 | AB4: ='Daily Energy'!AB4/'Daily Energy'!$B4 -> 0 | AC4: ='Daily Energy'!AC4/'Daily Energy'!$B4 -> 0 | AD4: ='Daily Energy'!AD4/'Daily Energy'!$B4 -> 0 | AE4: ='Daily Energy'!AE4/'Daily Energy'!$B4 -> 0 | AF4: ='Daily Energy'!AF4/'Daily Energy'!$B4 -> 0 | AG4: ='Daily Energy'!AG4/'Daily Energy'!$B4 -> 0
A5: INV-3 | B5: 127.53 | C5: 501 | D5: ='Daily Energy'!D6/'Daily Energy'!$B5 -> 0 | E5: ='Daily Energy'!E5/'Daily Energy'!$B5 -> 0 | F5: ='Daily Energy'!F5/'Daily Energy'!$B5 -> 0 | G5: ='Daily Energy'!G5/'Daily Energy'!$B5 -> 0 | H5: ='Daily Energy'!H5/'Daily Energy'!$B5 -> 0 | I5: ='Daily Energy'!I5/'Daily Energy'!$B5 -> 0 | J5: ='Daily Energy'!J5/'Daily Energy'!$B5 -> 0 | K5: ='Daily Energy'!K5/'Daily Energy'!$B5 -> 0 | L5: ='Daily Energy'!L5/'Daily Energy'!$B5 -> 0 | ... O5: ='Daily Energy'!O5/'Daily Energy'!$B5 -> 0 | P5: ='Daily Energy'!#REF!/'Daily Energy'!$B5 -> #REF! | Q5: ='Daily Energy'!Q5/'Daily Energy'!$B5 -> 2.0073708 | R5: ='Daily Energy'!R5/'Daily Energy'!$B5 -> 0 | S5: ='Daily Energy'!S5/'Daily Energy'!$B5 -> 0 | T5: ='Daily Energy'!T5/'Daily Energy'!$B5 -> 2.3523877 | U5: ='Daily Energy'!U5/'Daily Energy'!$B5 -> 0 | V5: ='Daily Energy'!W5/'Daily Energy'!$B5 -> 0 | W5: ='Daily Energy'!X5/'Daily Energy'!$B5 -> 0 | X5: ='Daily Energy'!Z5/'Daily Energy'!$B5 -> 0 | Y5: ='Daily Energy'!#REF!/'Daily Energy'!$B5 -> #REF! | Z5: ='Daily Energy'!#REF!/'Daily Energy'!$B5 -> #REF! | AA5: ='Daily Energy'!AA5/'Daily Energy'!$B5 -> 0 | AB5: ='Daily Energy'!AB5/'Daily Energy'!$B5 -> 0 | AC5: ='Daily Energy'!AC5/'Daily Energy'!$B5 -> 0 | AD5: ='Daily Energy'!AD5/'Daily Energy'!$B5 -> 0 | AE5: ='Daily Energy'!AE5/'Daily Energy'!$B5 -> 0 | AF5: ='Daily Energy'!AF5/'Daily Energy'!$B5 -> 0 | AG5: ='Daily Energy'!AG5/'Daily Energy'!$B5 -> 0
A6: INV-4 | B6: 127.53 | C6: 477 | D6: ='Daily Energy'!D7/'Daily Energy'!$B6 -> 0 | E6: ='Daily Energy'!E6/'Daily Energy'!$B6 -> 0 | F6: ='Daily Energy'!F6/'Daily Energy'!$B6 -> 0 | G6: ='Daily Energy'!G6/'Daily Energy'!$B6 -> 0 | H6: ='Daily Energy'!H6/'Daily Energy'!$B6 -> 0 | I6: ='Daily Energy'!I6/'Daily Energy'!$B6 -> 0 | J6: ='Daily Energy'!J6/'Daily Energy'!$B6 -> 0 | K6: ='Daily Energy'!K6/'Daily Energy'!$B6 -> 0 | L6: ='Daily Energy'!L6/'Daily Energy'!$B6 -> 0 | ... O6: ='Daily Energy'!O6/'Daily Energy'!$B6 -> 0 | P6: ='Daily Energy'!P5/'Daily Energy'!$B6 -> 1.905434 | Q6: ='Daily Energy'!Q6/'Daily Energy'!$B6 -> 1.8427037 | R6: ='Daily Energy'!R6/'Daily Energy'!$B6 -> 0 | S6: ='Daily Energy'!S6/'Daily Energy'!$B6 -> 0 | T6: ='Daily Energy'!T6/'Daily Energy'!$B6 -> 2.1563554 | U6: ='Daily Energy'!U6/'Daily Energy'!$B6 -> 0 | V6: ='Daily Energy'!W6/'Daily Energy'!$B6 -> 0 | W6: ='Daily Energy'!X6/'Daily Energy'!$B6 -> 0 | X6: ='Daily Energy'!Z6/'Daily Energy'!$B6 -> 0 | Y6: ='Daily Energy'!#REF!/'Daily Energy'!$B6 -> #REF! | Z6: ='Daily Energy'!#REF!/'Daily Energy'!$B6 -> #REF! | AA6: ='Daily Energy'!AA6/'Daily Energy'!$B6 -> 0 | AB6: ='Daily Energy'!AB6/'Daily Energy'!$B6 -> 0 | AC6: ='Daily Energy'!AC6/'Daily Energy'!$B6 -> 0 | AD6: ='Daily Energy'!AD6/'Daily Energy'!$B6 -> 0 | AE6: ='Daily Energy'!AE6/'Daily Energy'!$B6 -> 0 | AF6: ='Daily Energy'!AF6/'Daily Energy'!$B6 -> 0 | AG6: ='Daily Energy'!AG6/'Daily Energy'!$B6 -> 0
A7: INV-5 | B7: 127.53 | C7: 446 | D7: ='Daily Energy'!D8/'Daily Energy'!$B7 -> 0 | E7: ='Daily Energy'!E7/'Daily Energy'!$B7 -> 0 | F7: ='Daily Energy'!F7/'Daily Energy'!$B7 -> 0 | G7: ='Daily Energy'!G7/'Daily Energy'!$B7 -> 0 | H7: ='Daily Energy'!H7/'Daily Energy'!$B7 -> 0 | I7: ='Daily Energy'!I7/'Daily Energy'!$B7 -> 0 | J7: ='Daily Energy'!J7/'Daily Energy'!$B7 -> 0 | K7: ='Daily Energy'!K7/'Daily Energy'!$B7 -> 0 | L7: ='Daily Energy'!L7/'Daily Energy'!$B7 -> 0 | ... O7: ='Daily Energy'!O7/'Daily Energy'!$B7 -> 0 | P7: ='Daily Energy'!P6/'Daily Energy'!$B7 -> 1.6701952 | Q7: ='Daily Energy'!Q7/'Daily Energy'!$B7 -> 2.0152121 | R7: ='Daily Energy'!R7/'Daily Energy'!$B7 -> 0 | S7: ='Daily Energy'!S7/'Daily Energy'!$B7 -> 0 | T7: ='Daily Energy'!T7/'Daily Energy'!$B7 -> 2.4386419 | U7: ='Daily Energy'!U7/'Daily Energy'!$B7 -> 0 | V7: ='Daily Energy'!W7/'Daily Energy'!$B7 -> 0 | W7: ='Daily Energy'!X7/'Daily Energy'!$B7 -> 0 | X7: ='Daily Energy'!Z7/'Daily Energy'!$B7 -> 0 | Y7: ='Daily Energy'!#REF!/'Daily Energy'!$B7 -> #REF! | Z7: ='Daily Energy'!#REF!/'Daily Energy'!$B7 -> #REF! | AA7: ='Daily Energy'!AA7/'Daily Energy'!$B7 -> 0 | AB7: ='Daily Energy'!AB7/'Daily Energy'!$B7 -> 0 | AC7: ='Daily Energy'!AC7/'Daily Energy'!$B7 -> 0 | AD7: ='Daily Energy'!AD7/'Daily Energy'!$B7 -> 0 | AE7: ='Daily Energy'!#REF!/'Daily Energy'!$B7 -> #REF! | AF7: ='Daily Energy'!AF7/'Daily Energy'!$B7 -> 0 | AG7: ='Daily Energy'!AG7/'Daily Energy'!$B7 -> 0
A8: INV-6 | B8: 127.53 | C8: 486 | D8: ='Daily Energy'!D9/'Daily Energy'!$B8 -> 0 | E8: ='Daily Energy'!E8/'Daily Energy'!$B8 -> 0 | F8: ='Daily Energy'!F8/'Daily Energy'!$B8 -> 0 | G8: ='Daily Energy'!G8/'Daily Energy'!$B8 -> 0 | H8: ='Daily Energy'!#REF!/'Daily Energy'!$B8 -> #REF! | I8: ='Daily Energy'!I8/'Daily Energy'!$B8 -> 0 | J8: ='Daily Energy'!J8/'Daily Energy'!$B8 -> 0 | K8: ='Daily Energy'!K8/'Daily Energy'!$B8 -> 0 | L8: ='Daily Energy'!L8/'Daily Energy'!$B8 -> 0 | M8: ='Daily Energy'!M8/'Daily Energy'!$B8 -> 0 | N8: ='Daily Energy'!N8/'Daily Energy'!$B8 -> 0 | O8: ='Daily Energy'!O8/'Daily Energy'!$B8 -> 0 | P8: ='Daily Energy'!P7/'Daily Energy'!$B8 -> 1.9681644 | Q8: ='Daily Energy'!Q8/'Daily Energy'!$B8 -> 1.9132753 | R8: ='Daily Energy'!R8/'Daily Energy'!$B8 -> 0 | S8: ='Daily Energy'!S8/'Daily Energy'!$B8 -> 0 | T8: ='Daily Energy'!T8/'Daily Energy'!$B8 -> 2.2661335 | U8: ='Daily Energy'!U8/'Daily Energy'!$B8 -> 0 | V8: ='Daily Energy'!W8/'Daily Energy'!$B8 -> 0 | W8: ='Daily Energy'!X8/'Daily Energy'!$B8 -> 0 | X8: ='Daily Energy'!Z8/'Daily Energy'!$B8 -> 0 | Y8: ='Daily Energy'!#REF!/'Daily Energy'!$B8 -> #REF! | Z8: ='Daily Energy'!#REF!/'Daily Energy'!$B8 -> #REF! | AA8: ='Daily Energy'!AA8/'Daily Energy'!$B8 -> 0 | AB8: ='Daily Energy'!AB8/'Daily Energy'!$B8 -> 0 | AC8: ='Daily Energy'!AC8/'Daily Energy'!$B8 -> 0 | AD8: ='Daily Energy'!AD8/'Daily Energy'!$B8 -> 0 | AE8: ='Daily Energy'!AE7/'Daily Energy'!$B8 -> 0 | AF8: ='Daily Energy'!AF8/'Daily Energy'!$B8 -> 0 | AG8: ='Daily Energy'!AG8/'Daily Energy'!$B8 -> 0
A9: INV-7 | B9: 137.34 | C9: 516 | D9: ='Daily Energy'!D10/'Daily Energy'!$B9 -> 0 | E9: ='Daily Energy'!E9/'Daily Energy'!$B9 -> 0 | F9: ='Daily Energy'!F9/'Daily Energy'!$B9 -> 0 | G9: ='Daily Energy'!G9/'Daily Energy'!$B9 -> 0 | H9: ='Daily Energy'!H8/'Daily Energy'!$B9 -> 0 | I9: ='Daily Energy'!I9/'Daily Energy'!$B9 -> 0 | J9: ='Daily Energy'!J9/'Daily Energy'!$B9 -> 0 | K9: ='Daily Energy'!K9/'Daily Energy'!$B9 -> 0 | L9: ='Daily Energy'!L9/'Daily Energy'!$B9 -> 0 | M9: ='Daily Energy'!M9/'Daily Energy'!$B9 -> 0 | N9: ='Daily Energy'!N9/'Daily Energy'!$B9 -> 0 | O9: ='Daily Energy'!O9/'Daily Energy'!$B9 -> 0 | P9: ='Daily Energy'!P8/'Daily Energy'!$B9 -> 1.7256444 | Q9: ='Daily Energy'!Q9/'Daily Energy'!$B9 -> 1.893112 | R9: ='Daily Energy'!R9/'Daily Energy'!$B9 -> 0 | S9: ='Daily Energy'!S9/'Daily Energy'!$B9 -> 0 | T9: ='Daily Energy'!T9/'Daily Energy'!$B9 -> 2.293578 | U9: ='Daily Energy'!U9/'Daily Energy'!$B9 -> 0 | V9: ='Daily Energy'!W9/'Daily Energy'!$B9 -> 0 | W9: ='Daily Energy'!X9/'Daily Energy'!$B9 -> 0 | X9: ='Daily Energy'!Z9/'Daily Energy'!$B9 -> 0 | Y9: ='Daily Energy'!#REF!/'Daily Energy'!$B9 -> #REF! | Z9: ='Daily Energy'!#REF!/'Daily Energy'!$B9 -> #REF! | AA9: ='Daily Energy'!AA9/'Daily Energy'!$B9 -> 0 | AB9: ='Daily Energy'!AB9/'Daily Energy'!$B9 -> 0 | AC9: ='Daily Energy'!AC9/'Daily Energy'!$B9 -> 0 | AD9: ='Daily Energy'!AD9/'Daily Energy'!$B9 -> 0 | AE9: ='Daily Energy'!AE8/'Daily Energy'!$B9 -> 0 | AF9: ='Daily Energy'!AF9/'Daily Energy'!$B9 -> 0 | AG9: ='Daily Energy'!AG9/'Daily Energy'!$B9 -> 0
A10: INV-8 | B10: 137.34 | C10: 534 | D10: ='Daily Energy'!D11/'Daily Energy'!$B10 -> 0 | E10: ='Daily Energy'!E10/'Daily Energy'!$B10 -> 0 | F10: ='Daily Energy'!F10/'Daily Energy'!$B10 -> 0 | G10: ='Daily Energy'!G10/'Daily Energy'!$B10 -> 0 | H10: ='Daily Energy'!H9/'Daily Energy'!$B10 -> 0 | I10: ='Daily Energy'!I10/'Daily Energy'!$B10 -> 0 | J10: ='Daily Energy'!J10/'Daily Energy'!$B10 -> 0 | K10: ='Daily Energy'!K10/'Daily Energy'!$B10 -> 0 | L10: ='Daily Energy'!L10/'Daily Energy'!$B10 -> 0 | M10: ='Daily Energy'!M10/'Daily Energy'!$B10 -> 0 | N10: ='Daily Energy'!N10/'Daily Energy'!$B10 -> 0 | O10: ='Daily Energy'!O10/'Daily Energy'!$B10 -> 0 | P10: ='Daily Energy'!P10/'Daily Energy'!$B10 -> 1.6819572 | ... U10: ='Daily Energy'!U10/'Daily Energy'!$B10 -> 0 | V10: ='Daily Energy'!W10/'Daily Energy'!$B10 -> 0 | W10: ='Daily Energy'!X10/'Daily Energy'!$B10 -> 0 | X10: ='Daily Energy'!Z10/'Daily Energy'!$B10 -> 0 | Y10: ='Daily Energy'!#REF!/'Daily Energy'!$B10 -> #REF! | Z10: ='Daily Energy'!#REF!/'Daily Energy'!$B10 -> #REF! | AA10: ='Daily Energy'!AA10/'Daily Energy'!$B10 -> 0 | AB10: ='Daily Energy'!AB10/'Daily Energy'!$B10 -> 0 | AC10: ='Daily Energy'!AC10/'Daily Energy'!$B10 -> 0 | AD10: ='Daily Energy'!AD10/'Daily Energy'!$B10 -> 0 | AE10: ='Daily Energy'!AE9/'Daily Energy'!$B10 -> 0 | AF10: ='Daily Energy'!AF10/'Daily Energy'!$B10 -> 0 | AG10: ='Daily Energy'!AG10/'Daily Energy'!$B10 -> 0
A11: INV-9 | B11: 137.34 | C11: 533 | D11: ='Daily Energy'!D12/'Daily Energy'!$B11 -> 0 | E11: ='Daily Energy'!E11/'Daily Energy'!$B11 -> 0 | F11: ='Daily Energy'!F11/'Daily Energy'!$B11 -> 0 | G11: ='Daily Energy'!G11/'Daily Energy'!$B11 -> 0 | H11: ='Daily Energy'!H10/'Daily Energy'!$B11 -> 0 | I11: ='Daily Energy'!I11/'Daily Energy'!$B11 -> 0 | J11: ='Daily Energy'!J11/'Daily Energy'!$B11 -> 0 | K11: ='Daily Energy'!K11/'Daily Energy'!$B11 -> 0 | L11: ='Daily Energy'!L12/'Daily Energy'!$B11 -> 0 | M11: ='Daily Energy'!M11/'Daily Energy'!$B11 -> 0 | N11: ='Daily Energy'!N11/'Daily Energy'!$B11 -> 0 | O11: ='Daily Energy'!O11/'Daily Energy'!$B11 -> 0 | P11: ='Daily Energy'!P11/'Daily Energy'!$B11 -> 1.8203 | Q11: ='Daily Energy'!Q11/'Daily Energy'!$B11 -> 1.8639872 | R11: ='Daily Energy'!R11/'Daily Energy'!$B11 -> 0 | S11: ='Daily Energy'!S11/'Daily Energy'!$B11 -> 0 | T11: ='Daily Energy'!T11/'Daily Energy'!$B11 -> 2.220766 | U11: ='Daily Energy'!U11/'Daily Energy'!$B11 -> 0 | V11: ='Daily Energy'!W11/'Daily Energy'!$B11 -> 0 | W11: ='Daily Energy'!X11/'Daily Energy'!$B11 -> 0 | X11: ='Daily Energy'!Z11/'Daily Energy'!$B11 -> 0 | Y11: ='Daily Energy'!#REF!/'Daily Energy'!$B11 -> #REF! | Z11: ='Daily Energy'!#REF!/'Daily Energy'!$B11 -> #REF! | AA11: ='Daily Energy'!AA11/'Daily Energy'!$B11 -> 0 | AB11: ='Daily Energy'!AB11/'Daily Energy'!$B11 -> 0 | AC11: ='Daily Energy'!#REF!/'Daily Energy'!$B11 -> #REF! | AD11: ='Daily Energy'!AD11/'Daily Energy'!$B11 -> 0 | AE11: ='Daily Energy'!AE10/'Daily Energy'!$B11 -> 0 | AF11: ='Daily Energy'!AF11/'Daily Energy'!$B11 -> 0 | AG11: ='Daily Energy'!AG11/'Daily Energy'!$B11 -> 0
A12: INV-10 | B12: 137.34 | C12: 513 | D12: ='Daily Energy'!D13/'Daily Energy'!$B12 -> 0 | E12: ='Daily Energy'!E12/'Daily Energy'!$B12 -> 0 | F12: ='Daily Energy'!F12/'Daily Energy'!$B12 -> 0 | G12: ='Daily Energy'!G12/'Daily Energy'!$B12 -> 0 | H12: ='Daily Energy'!H11/'Daily Energy'!$B12 -> 0 | I12: ='Daily Energy'!I12/'Daily Energy'!$B12 -> 0 | J12: ='Daily Energy'!J12/'Daily Energy'!$B12 -> 0 | K12: ='Daily Energy'!K12/'Daily Energy'!$B12 -> 0 | L12: ='Daily Energy'!L13/'Daily Energy'!$B12 -> 0 | M12: ='Daily Energy'!M12/'Daily Energy'!$B12 -> 0 | N12: ='Daily Energy'!N12/'Daily Energy'!$B12 -> 0 | O12: ='Daily Energy'!O12/'Daily Energy'!$B12 -> 0 | P12: ='Daily Energy'!P12/'Daily Energy'!$B12 -> 1.893112 | Q12: ='Daily Energy'!Q12/'Daily Energy'!$B12 -> 1.747488 | R12: ='Daily Energy'!R12/'Daily Energy'!$B12 -> 0 | S12: ='Daily Energy'!S12/'Daily Energy'!$B12 -> 0 | T12: ='Daily Energy'!T12/'Daily Energy'!$B12 -> 2.2717344 | U12: ='Daily Energy'!U12/'Daily Energy'!$B12 -> 0 | V12: ='Daily Energy'!W12/'Daily Energy'!$B12 -> 0 | W12: ='Daily Energy'!X12/'Daily Energy'!$B12 -> 0 | X12: ='Daily Energy'!Z12/'Daily Energy'!$B12 -> 0 | Y12: ='Daily Energy'!#REF!/'Daily Energy'!$B12 -> #REF! | Z12: ='Daily Energy'!#REF!/'Daily Energy'!$B12 -> #REF! | AA12: ='Daily Energy'!AA12/'Daily Energy'!$B12 -> 0 | AB12: ='Daily Energy'!AB12/'Daily Energy'!$B12 -> 0 | AC12: ='Daily Energy'!AC11/'Daily Energy'!$B12 -> 0 | AD12: ='Daily Energy'!AD12/'Daily Energy'!$B12 -> 0 | AE12: ='Daily Energy'!AE11/'Daily Energy'!$B12 -> 0 | AF12: ='Daily Energy'!AF12/'Daily Energy'!$B12 -> 0 | AG12: ='Daily Energy'!AG12/'Daily Energy'!$B12 -> 0
A13: INV-11 | B13: 137.34 | C13: 516 | D13: ='Daily Energy'!#REF!/'Daily Energy'!$B13 -> #REF! | E13: ='Daily Energy'!E13/'Daily Energy'!$B13 -> 0 | F13: ='Daily Energy'!F13/'Daily Energy'!$B13 -> 0 | G13: ='Daily Energy'!G13/'Daily Energy'!$B13 -> 0 | H13: ='Daily Energy'!H12/'Daily Energy'!$B13 -> 0 | I13: ='Daily Energy'!I13/'Daily Energy'!$B13 -> 0 | J13: ='Daily Energy'!J13/'Daily Energy'!$B13 -> 0 | K13: ='Daily Energy'!K13/'Daily Energy'!$B13 -> 0 | L13: ='Daily Energy'!L13/'Daily Energy'!$B13 -> 0 | M13: ='Daily Energy'!M13/'Daily Energy'!$B13 -> 0 | N13: ='Daily Energy'!N13/'Daily Energy'!$B13 -> 0 | O13: ='Daily Energy'!O13/'Daily Energy'!$B13 -> 0 | P13: ='Daily Energy'!P13/'Daily Energy'!$B13 -> 1.6819572 | ... U13: ='Daily Energy'!U13/'Daily Energy'!$B13 -> 0 | V13: ='Daily Energy'!W13/'Daily Energy'!$B13 -> 0 | W13: ='Daily Energy'!X13/'Daily Energy'!$B13 -> 0 | X13: ='Daily Energy'!Z13/'Daily Energy'!$B13 -> 0 | Y13: ='Daily Energy'!#REF!/'Daily Energy'!$B13 -> #REF! | Z13: ='Daily Energy'!#REF!/'Daily Energy'!$B13 -> #REF! | AA13: ='Daily Energy'!AA13/'Daily Energy'!$B13 -> 0 | AB13: ='Daily Energy'!AB13/'Daily Energy'!$B13 -> 0 | AC13: ='Daily Energy'!AC12/'Daily Energy'!$B13 -> 0 | AD13: ='Daily Energy'!AD13/'Daily Energy'!$B13 -> 0 | AE13: ='Daily Energy'!AE12/'Daily Energy'!$B13 -> 0 | AF13: ='Daily Energy'!AF13/'Daily Energy'!$B13 -> 0 | AG13: ='Daily Energy'!AG13/'Daily Energy'!$B13 -> 0
A14: INV-12 | B14: 127.53 | C14: 477 | D14: ='Daily Energy'!D14/'Daily Energy'!$B14 -> 0 | E14: ='Daily Energy'!E14/'Daily Energy'!$B14 -> 0 | F14: ='Daily Energy'!F14/'Daily Energy'!$B14 -> 0 | G14: ='Daily Energy'!G14/'Daily Energy'!$B14 -> 0 | H14: ='Daily Energy'!H13/'Daily Energy'!$B14 -> 0 | I14: ='Daily Energy'!I14/'Daily Energy'!$B14 -> 0 | J14: ='Daily Energy'!J14/'Daily Energy'!$B14 -> 0 | K14: ='Daily Energy'!K14/'Daily Energy'!$B14 -> 0 | L14: ='Daily Energy'!L14/'Daily Energy'!$B14 -> 0 | M14: ='Daily Energy'!M14/'Daily Energy'!$B14 -> 0 | N14: ='Daily Energy'!N14/'Daily Energy'!$B14 -> 0 | O14: ='Daily Energy'!O14/'Daily Energy'!$B14 -> 0 | P14: ='Daily Energy'!P14/'Daily Energy'!$B14 -> 1.9760056 | ... U14: ='Daily Energy'!U14/'Daily Energy'!$B14 -> 0 | V14: ='Daily Energy'!W14/'Daily Energy'!$B14 -> 0 | W14: ='Daily Energy'!X14/'Daily Energy'!$B14 -> 0 | X14: ='Daily Energy'!Z14/'Daily Energy'!$B14 -> 0 | Y14: ='Daily Energy'!#REF!/'Daily Energy'!$B14 -> #REF! | Z14: ='Daily Energy'!#REF!/'Daily Energy'!$B14 -> #REF! | AA14: ='Daily Energy'!AA14/'Daily Energy'!$B14 -> 0 | AB14: ='Daily Energy'!AB14/'Daily Energy'!$B14 -> 0 | AC14: ='Daily Energy'!AC13/'Daily Energy'!$B14 -> 0 | AD14: ='Daily Energy'!AD14/'Daily Energy'!$B14 -> 0 | AE14: ='Daily Energy'!AE13/'Daily Energy'!$B14 -> 0 | AF14: ='Daily Energy'!AF14/'Daily Energy'!$B14 -> 0 | AG14: ='Daily Energy'!AG14/'Daily Energy'!$B14 -> 0
A15: INV-13 | B15: 127.53 | C15: 473 | D15: ='Daily Energy'!D15/'Daily Energy'!$B15 -> 0 | E15: ='Daily Energy'!E15/'Daily Energy'!$B15 -> 0 | F15: ='Daily Energy'!F15/'Daily Energy'!$B15 -> 0 | G15: ='Daily Energy'!G15/'Daily Energy'!$B15 -> 0 | H15: ='Daily Energy'!H14/'Daily Energy'!$B15 -> 0 | I15: ='Daily Energy'!I15/'Daily Energy'!$B15 -> 0 | J15: ='Daily Energy'!J15/'Daily Energy'!$B15 -> 0 | K15: ='Daily Energy'!K15/'Daily Energy'!$B15 -> 0 | L15: ='Daily Energy'!L15/'Daily Energy'!$B15 -> 0 | M15: ='Daily Energy'!M15/'Daily Energy'!$B15 -> 0 | N15: ='Daily Energy'!N15/'Daily Energy'!$B15 -> 0 | O15: ='Daily Energy'!O15/'Daily Energy'!$B15 -> 0 | P15: ='Daily Energy'!P15/'Daily Energy'!$B15 -> 1.8740688 | ... S15: ='Daily Energy'!S15/'Daily Energy'!$B15 -> 0 | T15: ='Daily Energy'!T16/'Daily Energy'!$B15 -> 0 | U15: ='Daily Energy'!U15/'Daily Energy'!$B15 -> 0 | V15: ='Daily Energy'!W15/'Daily Energy'!$B15 -> 0 | W15: ='Daily Energy'!X15/'Daily Energy'!$B15 -> 0 | X15: ='Daily Energy'!Z15/'Daily Energy'!$B15 -> 0 | Y15: ='Daily Energy'!#REF!/'Daily Energy'!$B15 -> #REF! | Z15: ='Daily Energy'!#REF!/'Daily Energy'!$B15 -> #REF! | AA15: ='Daily Energy'!AA15/'Daily Energy'!$B15 -> 0 | AB15: ='Daily Energy'!AB15/'Daily Energy'!$B15 -> 0 | AC15: ='Daily Energy'!AC14/'Daily Energy'!$B15 -> 0 | AD15: ='Daily Energy'!AD15/'Daily Energy'!$B15 -> 0 | AE15: ='Daily Energy'!AE14/'Daily Energy'!$B15 -> 0 | AF15: ='Daily Energy'!AF15/'Daily Energy'!$B15 -> 0 | AG15: ='Daily Energy'!AG15/'Daily Energy'!$B15 -> 0
A16: INV-14 | B16: 127.53 | C16: 470 | D16: ='Daily Energy'!D16/'Daily Energy'!$B16 -> 0 | E16: ='Daily Energy'!E16/'Daily Energy'!$B16 -> 0 | F16: ='Daily Energy'!F16/'Daily Energy'!$B16 -> 0 | G16: ='Daily Energy'!G16/'Daily Energy'!$B16 -> 0 | H16: ='Daily Energy'!H15/'Daily Energy'!$B16 -> 0 | I16: ='Daily Energy'!I16/'Daily Energy'!$B16 -> 0 | J16: ='Daily Energy'!J16/'Daily Energy'!$B16 -> 0 | K16: ='Daily Energy'!K16/'Daily Energy'!$B16 -> 0 | L16: ='Daily Energy'!L16/'Daily Energy'!$B16 -> 0 | M16: ='Daily Energy'!M16/'Daily Energy'!$B16 -> 0 | N16: ='Daily Energy'!N16/'Daily Energy'!$B16 -> 0 | O16: ='Daily Energy'!O16/'Daily Energy'!$B16 -> 0 | P16: ='Daily Energy'!P16/'Daily Energy'!$B16 -> 0 | ... S16: ='Daily Energy'!S16/'Daily Energy'!$B16 -> 0 | T16: ='Daily Energy'!T17/'Daily Energy'!$B16 -> 0 | U16: ='Daily Energy'!U16/'Daily Energy'!$B16 -> 0 | V16: ='Daily Energy'!W16/'Daily Energy'!$B16 -> 0 | W16: ='Daily Energy'!X16/'Daily Energy'!$B16 -> 0 | X16: ='Daily Energy'!Z16/'Daily Energy'!$B16 -> 0 | Y16: ='Daily Energy'!#REF!/'Daily Energy'!$B16 -> #REF! | Z16: ='Daily Energy'!#REF!/'Daily Energy'!$B16 -> #REF! | AA16: ='Daily Energy'!AA16/'Daily Energy'!$B16 -> 0 | AB16: ='Daily Energy'!AB16/'Daily Energy'!$B16 -> 0 | AC16: ='Daily Energy'!AC15/'Daily Energy'!$B16 -> 0 | AD16: ='Daily Energy'!AD16/'Daily Energy'!$B16 -> 0 | AE16: ='Daily Energy'!AE15/'Daily Energy'!$B16 -> 0 | AF16: ='Daily Energy'!AF16/'Daily Energy'!$B16 -> 0 | AG16: ='Daily Energy'!AG16/'Daily Energy'!$B16 -> 0
A17: INV-15 | B17: 127.53 | C17: 465 | D17: ='Daily Energy'!D17/'Daily Energy'!$B17 -> 0 | E17: ='Daily Energy'!E17/'Daily Energy'!$B17 -> 0 | F17: ='Daily Energy'!F17/'Daily Energy'!$B17 -> 0 | G17: ='Daily Energy'!G17/'Daily Energy'!$B17 -> 0 | H17: ='Daily Energy'!H16/'Daily Energy'!$B17 -> 0 | I17: ='Daily Energy'!I17/'Daily Energy'!$B17 -> 0 | J17: ='Daily Energy'!J17/'Daily Energy'!$B17 -> 0 | K17: ='Daily Energy'!K17/'Daily Energy'!$B17 -> 0 | L17: ='Daily Energy'!L17/'Daily Energy'!$B17 -> 0 | M17: ='Daily Energy'!M17/'Daily Energy'!$B17 -> 0 | N17: ='Daily Energy'!N17/'Daily Energy'!$B17 -> 0 | O17: ='Daily Energy'!O17/'Daily Energy'!$B17 -> 0 | P17: ='Daily Energy'!P17/'Daily Energy'!$B17 -> 0 | ... S17: ='Daily Energy'!S17/'Daily Energy'!$B17 -> 0 | T17: ='Daily Energy'!T18/'Daily Energy'!$B17 -> 0 | U17: ='Daily Energy'!U17/'Daily Energy'!$B17 -> 0 | V17: ='Daily Energy'!W17/'Daily Energy'!$B17 -> 0 | W17: ='Daily Energy'!X17/'Daily Energy'!$B17 -> 0 | X17: ='Daily Energy'!Z17/'Daily Energy'!$B17 -> 0 | Y17: ='Daily Energy'!#REF!/'Daily Energy'!$B17 -> #REF! | Z17: ='Daily Energy'!#REF!/'Daily Energy'!$B17 -> #REF! | AA17: ='Daily Energy'!AA17/'Daily Energy'!$B17 -> 0 | AB17: ='Daily Energy'!AB17/'Daily Energy'!$B17 -> 0 | AC17: ='Daily Energy'!AC16/'Daily Energy'!$B17 -> 0 | AD17: ='Daily Energy'!AD17/'Daily Energy'!$B17 -> 0 | AE17: ='Daily Energy'!AE16/'Daily Energy'!$B17 -> 0 | AF17: ='Daily Energy'!AF17/'Daily Energy'!$B17 -> 0 | AG17: ='Daily Energy'!AG17/'Daily Energy'!$B17 -> 0
A18: INV-16 | B18: 127.53 | C18: 478 | D18: ='Daily Energy'!D18/'Daily Energy'!$B18 -> 0 | E18: ='Daily Energy'!E18/'Daily Energy'!$B18 -> 0 | F18: ='Daily Energy'!F18/'Daily Energy'!$B18 -> 0 | G18: ='Daily Energy'!G18/'Daily Energy'!$B18 -> 0 | H18: ='Daily Energy'!H17/'Daily Energy'!$B18 -> 0 | I18: ='Daily Energy'!I14/'Daily Energy'!$B14 -> 0 | J18: ='Daily Energy'!J18/'Daily Energy'!$B18 -> 0 | K18: ='Daily Energy'!K18/'Daily Energy'!$B18 -> 0 | L18: ='Daily Energy'!L18/'Daily Energy'!$B18 -> 0 | M18: ='Daily Energy'!M18/'Daily Energy'!$B18 -> 0 | N18: ='Daily Energy'!N18/'Daily Energy'!$B18 -> 0 | O18: ='Daily Energy'!O14/'Daily Energy'!$B14 -> 0 | P18: ='Daily Energy'!P18/'Daily Energy'!$B18 -> 0 | Q18: ='Daily Energy'!Q18/'Daily Energy'!$B18 -> 0 | R18: ='Daily Energy'!R18/'Daily Energy'!$B18 -> 0 | S18: ='Daily Energy'!S18/'Daily Energy'!$B18 -> 0 | T18: ='Daily Energy'!T19/'Daily Energy'!$B18 -> 0 | U18: ='Daily Energy'!U18/'Daily Energy'!$B18 -> 0 | V18: ='Daily Energy'!W18/'Daily Energy'!$B18 -> 0 | W18: ='Daily Energy'!X18/'Daily Energy'!$B18 -> 0 | X18: ='Daily Energy'!Z18/'Daily Energy'!$B18 -> 0 | Y18: ='Daily Energy'!#REF!/'Daily Energy'!$B18 -> #REF! | Z18: ='Daily Energy'!#REF!/'Daily Energy'!$B18 -> #REF! | AA18: ='Daily Energy'!AA18/'Daily Energy'!$B18 -> 0 | AB18: ='Daily Energy'!AB18/'Daily Energy'!$B18 -> 0 | AC18: ='Daily Energy'!AC17/'Daily Energy'!$B18 -> 0 | AD18: ='Daily Energy'!AD18/'Daily Energy'!$B18 -> 0 | AE18: ='Daily Energy'!AE17/'Daily Energy'!$B18 -> 0 | AF18: ='Daily Energy'!AF18/'Daily Energy'!$B18 -> 0 | AG18: ='Daily Energy'!AG18/'Daily Energy'!$B18 -> 0
A19: INV-17 | B19: 127.53 | C19: 480 | D19: ='Daily Energy'!D19/'Daily Energy'!$B19 -> 0 | E19: ='Daily Energy'!E19/'Daily Energy'!$B19 -> 0 | F19: ='Daily Energy'!F19/'Daily Energy'!$B19 -> 0 | G19: ='Daily Energy'!G19/'Daily Energy'!$B19 -> 0 | H19: ='Daily Energy'!H18/'Daily Energy'!$B19 -> 0 | I19: ='Daily Energy'!I19/'Daily Energy'!$B19 -> 0 | J19: ='Daily Energy'!J19/'Daily Energy'!$B19 -> 0 | K19: ='Daily Energy'!K19/'Daily Energy'!$B19 -> 0 | L19: ='Daily Energy'!L19/'Daily Energy'!$B19 -> 0 | M19: ='Daily Energy'!M19/'Daily Energy'!$B19 -> 0 | N19: ='Daily Energy'!N19/'Daily Energy'!$B19 -> 0 | O19: ='Daily Energy'!O19/'Daily Energy'!$B19 -> 0 | P19: ='Daily Energy'!P19/'Daily Energy'!$B19 -> 0 | ... S19: ='Daily Energy'!S19/'Daily Energy'!$B19 -> 0 | T19: ='Daily Energy'!T20/'Daily Energy'!$B19 -> 0 | U19: ='Daily Energy'!U19/'Daily Energy'!$B19 -> 0 | V19: ='Daily Energy'!W19/'Daily Energy'!$B19 -> 0 | W19: ='Daily Energy'!X19/'Daily Energy'!$B19 -> 0 | X19: ='Daily Energy'!Z19/'Daily Energy'!$B19 -> 0 | Y19: ='Daily Energy'!#REF!/'Daily Energy'!$B19 -> #REF! | Z19: ='Daily Energy'!#REF!/'Daily Energy'!$B19 -> #REF! | AA19: ='Daily Energy'!AA19/'Daily Energy'!$B19 -> 0 | AB19: ='Daily Energy'!AB19/'Daily Energy'!$B19 -> 0 | AC19: ='Daily Energy'!AC19/'Daily Energy'!$B19 -> 0 | AD19: ='Daily Energy'!AD19/'Daily Energy'!$B19 -> 0 | AE19: ='Daily Energy'!AE18/'Daily Energy'!$B19 -> 0 | AF19: ='Daily Energy'!AF19/'Daily Energy'!$B19 -> 0 | AG19: ='Daily Energy'!AG19/'Daily Energy'!$B19 -> 0
A20: INV-18 | B20: 137.34 | C20: 462 | D20: ='Daily Energy'!D20/'Daily Energy'!$B20 -> 0 | E20: ='Daily Energy'!E20/'Daily Energy'!$B20 -> 0 | F20: ='Daily Energy'!F20/'Daily Energy'!$B20 -> 0 | G20: ='Daily Energy'!G20/'Daily Energy'!$B20 -> 0 | H20: ='Daily Energy'!H20/'Daily Energy'!$B20 -> 0 | I20: ='Daily Energy'!I20/'Daily Energy'!$B20 -> 0 | J20: ='Daily Energy'!J20/'Daily Energy'!$B20 -> 0 | K20: ='Daily Energy'!K20/'Daily Energy'!$B20 -> 0 | ... S20: ='Daily Energy'!S20/'Daily Energy'!$B20 -> 0 | T20: ='Daily Energy'!T21/'Daily Energy'!$B20 -> 0 | U20: ='Daily Energy'!U20/'Daily Energy'!$B20 -> 0 | V20: ='Daily Energy'!W20/'Daily Energy'!$B20 -> 0 | W20: ='Daily Energy'!X20/'Daily Energy'!$B20 -> 0 | X20: ='Daily Energy'!Y20/'Daily Energy'!$B20 -> 0 | Y20: ='Daily Energy'!#REF!/'Daily Energy'!$B20 -> #REF! | Z20: ='Daily Energy'!Z20/'Daily Energy'!$B20 -> 0 | AA20: ='Daily Energy'!AA20/'Daily Energy'!$B20 -> 0 | AB20: ='Daily Energy'!AB20/'Daily Energy'!$B20 -> 0 | AC20: ='Daily Energy'!AC20/'Daily Energy'!$B20 -> 0 | AD20: ='Daily Energy'!AD20/'Daily Energy'!$B20 -> 0 | AE20: ='Daily Energy'!AE19/'Daily Energy'!$B20 -> 0 | AF20: ='Daily Energy'!AF20/'Daily Energy'!$B20 -> 0 | AG20: ='Daily Energy'!AG20/'Daily Energy'!$B20 -> 0
A21: INV-19 | B21: 137.34 | C21: 494 | D21: ='Daily Energy'!D21/'Daily Energy'!$B21 -> 0 | E21: ='Daily Energy'!E21/'Daily Energy'!$B21 -> 0 | F21: ='Daily Energy'!F21/'Daily Energy'!$B21 -> 0 | G21: ='Daily Energy'!G21/'Daily Energy'!$B21 -> 0 | H21: ='Daily Energy'!H21/'Daily Energy'!$B21 -> 0 | I21: ='Daily Energy'!I21/'Daily Energy'!$B21 -> 0 | J21: ='Daily Energy'!J21/'Daily Energy'!$B21 -> 0 | K21: ='Daily Energy'!K21/'Daily Energy'!$B21 -> 0 | ... N21: ='Daily Energy'!N21/'Daily Energy'!$B21 -> 0 | O21: ='Daily Energy'!O22/'Daily Energy'!$B21 -> 0 | P21: ='Daily Energy'!P21/'Daily Energy'!$B21 -> 0 | Q21: ='Daily Energy'!Q21/'Daily Energy'!$B21 -> 0 | R21: ='Daily Energy'!R21/'Daily Energy'!$B21 -> 0 | S21: ='Daily Energy'!S21/'Daily Energy'!$B21 -> 0 | T21: ='Daily Energy'!T22/'Daily Energy'!$B21 -> 0 | U21: ='Daily Energy'!U21/'Daily Energy'!$B21 -> 0 | V21: ='Daily Energy'!W21/'Daily Energy'!$B21 -> 0 | W21: ='Daily Energy'!X21/'Daily Energy'!$B21 -> 0 | X21: ='Daily Energy'!Y21/'Daily Energy'!$B21 -> 0 | Y21: ='Daily Energy'!#REF!/'Daily Energy'!$B21 -> #REF! | Z21: ='Daily Energy'!Z21/'Daily Energy'!$B21 -> 0 | AA21: ='Daily Energy'!AA21/'Daily Energy'!$B21 -> 0 | AB21: ='Daily Energy'!AB21/'Daily Energy'!$B21 -> 0 | AC21: ='Daily Energy'!AC21/'Daily Energy'!$B21 -> 0 | AD21: ='Daily Energy'!AD21/'Daily Energy'!$B21 -> 0 | AE21: ='Daily Energy'!AE20/'Daily Energy'!$B21 -> 0 | AF21: ='Daily Energy'!AF21/'Daily Energy'!$B21 -> 0 | AG21: ='Daily Energy'!AG21/'Daily Energy'!$B21 -> 0
A22: INV-20 | B22: 137.34 | C22: 480 | D22: ='Daily Energy'!D22/'Daily Energy'!$B22 -> 0 | E22: ='Daily Energy'!E22/'Daily Energy'!$B22 -> 0 | F22: ='Daily Energy'!F22/'Daily Energy'!$B22 -> 0 | G22: ='Daily Energy'!G22/'Daily Energy'!$B22 -> 0 | H22: ='Daily Energy'!H22/'Daily Energy'!$B22 -> 0 | I22: ='Daily Energy'!I22/'Daily Energy'!$B22 -> 0 | J22: ='Daily Energy'!J22/'Daily Energy'!$B22 -> 0 | K22: ='Daily Energy'!K22/'Daily Energy'!$B22 -> 0 | ... N22: ='Daily Energy'!N22/'Daily Energy'!$B22 -> 0 | O22: ='Daily Energy'!O23/'Daily Energy'!$B22 -> 0 | P22: ='Daily Energy'!P22/'Daily Energy'!$B22 -> 0 | Q22: ='Daily Energy'!Q22/'Daily Energy'!$B22 -> 0 | R22: ='Daily Energy'!R22/'Daily Energy'!$B22 -> 0 | S22: ='Daily Energy'!S22/'Daily Energy'!$B22 -> 0 | T22: ='Daily Energy'!T23/'Daily Energy'!$B22 -> 0 | U22: ='Daily Energy'!U22/'Daily Energy'!$B22 -> 0 | V22: ='Daily Energy'!W22/'Daily Energy'!$B22 -> 0 | W22: ='Daily Energy'!X22/'Daily Energy'!$B22 -> 0 | X22: ='Daily Energy'!Y22/'Daily Energy'!$B22 -> 0 | Y22: ='Daily Energy'!#REF!/'Daily Energy'!$B22 -> #REF! | Z22: ='Daily Energy'!Z22/'Daily Energy'!$B22 -> 0 | AA22: ='Daily Energy'!AA22/'Daily Energy'!$B22 -> 0 | AB22: ='Daily Energy'!AB22/'Daily Energy'!$B22 -> 0 | AC22: ='Daily Energy'!AC22/'Daily Energy'!$B22 -> 0 | AD22: ='Daily Energy'!AD22/'Daily Energy'!$B22 -> 0 | AE22: ='Daily Energy'!AE21/'Daily Energy'!$B22 -> 0 | AF22: ='Daily Energy'!AF22/'Daily Energy'!$B22 -> 0 | AG22: ='Daily Energy'!AG22/'Daily Energy'!$B22 -> 0
A23: INV-21 | B23: 137.34 | C23: 495 | D23: ='Daily Energy'!D23/'Daily Energy'!$B23 -> 0 | E23: ='Daily Energy'!E23/'Daily Energy'!$B23 -> 0 | F23: ='Daily Energy'!F23/'Daily Energy'!$B23 -> 0 | G23: ='Daily Energy'!G23/'Daily Energy'!$B23 -> 0 | H23: ='Daily Energy'!H23/'Daily Energy'!$B23 -> 0 | I23: ='Daily Energy'!I23/'Daily Energy'!$B23 -> 0 | J23: ='Daily Energy'!J23/'Daily Energy'!$B23 -> 0 | K23: ='Daily Energy'!K23/'Daily Energy'!$B23 -> 0 | ... S23: ='Daily Energy'!S23/'Daily Energy'!$B23 -> 0 | T23: ='Daily Energy'!#REF!/'Daily Energy'!$B23 -> #REF! | U23: ='Daily Energy'!U23/'Daily Energy'!$B23 -> 0 | V23: ='Daily Energy'!W23/'Daily Energy'!$B23 -> 0 | W23: ='Daily Energy'!X23/'Daily Energy'!$B23 -> 0 | X23: ='Daily Energy'!Y23/'Daily Energy'!$B23 -> 0 | Y23: ='Daily Energy'!#REF!/'Daily Energy'!$B23 -> #REF! | Z23: ='Daily Energy'!Z23/'Daily Energy'!$B23 -> 0 | AA23: ='Daily Energy'!AA23/'Daily Energy'!$B23 -> 0 | AB23: ='Daily Energy'!AB23/'Daily Energy'!$B23 -> 0 | AC23: ='Daily Energy'!AC23/'Daily Energy'!$B23 -> 0 | AD23: ='Daily Energy'!AD23/'Daily Energy'!$B23 -> 0 | AE23: ='Daily Energy'!AE22/'Daily Energy'!$B23 -> 0 | AF23: ='Daily Energy'!AF23/'Daily Energy'!$B23 -> 0 | AG23: ='Daily Energy'!AG23/'Daily Energy'!$B23 -> 0
A24: INV-22 | B24: 137.34 | C24: 495 | D24: ='Daily Energy'!D24/'Daily Energy'!$B24 -> 0 | E24: ='Daily Energy'!E24/'Daily Energy'!$B24 -> 0 | F24: ='Daily Energy'!F24/'Daily Energy'!$B24 -> 0 | G24: ='Daily Energy'!G24/'Daily Energy'!$B24 -> 0 | H24: ='Daily Energy'!H24/'Daily Energy'!$B24 -> 0 | I24: ='Daily Energy'!I24/'Daily Energy'!$B24 -> 0 | J24: ='Daily Energy'!J24/'Daily Energy'!$B24 -> 0 | K24: ='Daily Energy'!K24/'Daily Energy'!$B24 -> 0 | ... U24: ='Daily Energy'!U24/'Daily Energy'!$B24 -> 0 | V24: ='Daily Energy'!W24/'Daily Energy'!$B24 -> 0 | W24: ='Daily Energy'!X24/'Daily Energy'!$B24 -> 0 | X24: ='Daily Energy'!Y24/'Daily Energy'!$B24 -> 0 | Y24: ='Daily Energy'!#REF!/'Daily Energy'!$B24 -> #REF! | Z24: ='Daily Energy'!Z24/'Daily Energy'!$B24 -> 0 | AA24: ='Daily Energy'!AA24/'Daily Energy'!$B24 -> 0 | AB24: ='Daily Energy'!AB24/'Daily Energy'!$B24 -> 0 | AC24: ='Daily Energy'!AC24/'Daily Energy'!$B24 -> 0 | AD24: ='Daily Energy'!AD24/'Daily Energy'!$B24 -> 0 | AE24: ='Daily Energy'!AE23/'Daily Energy'!$B24 -> 0 | AF24: ='Daily Energy'!AF24/'Daily Energy'!$B24 -> 0 | AG24: ='Daily Energy'!AG24/'Daily Energy'!$B24 -> 0

Sheet Dev. w.r.t plots tracker
A1: RBA, Textiles
A2: INV NO | B2: ='Daily Energy'!C2 -> 46235 | C2: ='Daily Energy'!D2 -> 46236 | D2: ='Daily Energy'!E2 -> 46237 | E2: ='Daily Energy'!F2 -> 46238 | F2: ='Daily Energy'!G2 -> 46239 | G2: ='Daily Energy'!H2 -> 46240 | H2: ='Daily Energy'!I2 -> 46241 | I2: ='Daily Energy'!J2 -> 46242 | ... AF2: ='Daily Energy'!AG2 -> 46265
A3: INV-1 | B3: =IF(IFERROR('Daily SY'!C3/MAX('Daily SY'!C$3:C$15)-1,"")=-100%,"",IFERROR('Daily SY'!C3/MAX('Daily SY'!C$3:C$15)-1,"")) -> -0.084269663 | C3: =IF(IFERROR('Daily SY'!D3/MAX('Daily SY'!D$3:D$14)-1,"")=-100%,"",IFERROR('Daily SY'!D3/MAX('Daily SY'!D$3:D$14)-1,"")) | D3: =IF(IFERROR('Daily SY'!E3/MAX('Daily SY'!E$3:E$14)-1,"")=-100%,"",IFERROR('Daily SY'!E3/MAX('Daily SY'!E$3:E$14)-1,"")) | E3: =IF(IFERROR('Daily SY'!F3/MAX('Daily SY'!F$3:F$14)-1,"")=-100%,"",IFERROR('Daily SY'!F3/MAX('Daily SY'!F$3:F$14)-1,"")) | F3: =IF(IFERROR('Daily SY'!G3/MAX('Daily SY'!G$3:G$14)-1,"")=-100%,"",IFERROR('Daily SY'!G3/MAX('Daily SY'!G$3:G$14)-1,"")) | G3: =IF(IFERROR('Daily SY'!H3/MAX('Daily SY'!H$3:H$14)-1,"")=-100%,"",IFERROR('Daily SY'!H3/MAX('Daily SY'!H$3:H$14)-1,"")) | H3: =IF(IFERROR('Daily SY'!I3/MAX('Daily SY'!I$3:I$18)-1,"")=-100%,"",IFERROR('Daily SY'!I3/MAX('Daily SY'!I$3:I$18)-1,"")) | I3: =IF(IFERROR('Daily SY'!J3/MAX('Daily SY'!J$3:J$14)-1,"")=-100%,"",IFERROR('Daily SY'!J3/MAX('Daily SY'!J$3:J$14)-1,"")) | J3: =IF(IFERROR('Daily SY'!K3/MAX('Daily SY'!K$3:K$14)-1,"")=-100%,"",IFERROR('Daily SY'!K3/MAX('Daily SY'!K$3:K$14)-1,"")) | K3: =IF(IFERROR('Daily SY'!L3/MAX('Daily SY'!L$3:L$14)-1,"")=-100%,"",IFERROR('Daily SY'!L3/MAX('Daily SY'!L$3:L$14)-1,"")) | L3: =IF(IFERROR('Daily SY'!M3/MAX('Daily SY'!M$3:M$14)-1,"")=-100%,"",IFERROR('Daily SY'!M3/MAX('Daily SY'!M$3:M$14)-1,"")) | M3: =IF(IFERROR('Daily SY'!N3/MAX('Daily SY'!N$3:N$14)-1,"")=-100%,"",IFERROR('Daily SY'!N3/MAX('Daily SY'!N$3:N$14)-1,"")) | N3: =IF(IFERROR('Daily SY'!O3/MAX('Daily SY'!O$3:O$14)-1,"")=-100%,"",IFERROR('Daily SY'!O3/MAX('Daily SY'!O$3:O$14)-1,"")) | O3: =IF(IFERROR('Daily SY'!P3/MAX('Daily SY'!P$3:P$14)-1,"")=-100%,"",IFERROR('Daily SY'!P3/MAX('Daily SY'!P$3:P$14)-1,"")) | P3: =IF(IFERROR('Daily SY'!Q3/MAX('Daily SY'!Q$3:Q$14)-1,"")=-100%,"",IFERROR('Daily SY'!Q3/MAX('Daily SY'!Q$3:Q$14)-1,"")) -> -0.16153846 | ... AF3: =IF(IFERROR('Daily SY'!AG3/MAX('Daily SY'!AG$3:AG$14)-1,"")=-100%,"",IFERROR('Daily SY'!AG3/MAX('Daily SY'!AG$3:AG$14)-1,""))
A4: INV-2 | B4: =IF(IFERROR('Daily SY'!C4/MAX('Daily SY'!C$3:C$14)-1,"")=-100%,"",IFERROR('Daily SY'!C4/MAX('Daily SY'!C$3:C$14)-1,"")) -> -0.073033708 | C4: =IF(IFERROR('Daily SY'!D4/MAX('Daily SY'!D$3:D$14)-1,"")=-100%,"",IFERROR('Daily SY'!D4/MAX('Daily SY'!D$3:D$14)-1,"")) | D4: =IF(IFERROR('Daily SY'!E4/MAX('Daily SY'!E$3:E$14)-1,"")=-100%,"",IFERROR('Daily SY'!E4/MAX('Daily SY'!E$3:E$14)-1,"")) | E4: =IF(IFERROR('Daily SY'!F4/MAX('Daily SY'!F$3:F$14)-1,"")=-100%,"",IFERROR('Daily SY'!F4/MAX('Daily SY'!F$3:F$14)-1,"")) | F4: =IF(IFERROR('Daily SY'!G4/MAX('Daily SY'!G$3:G$14)-1,"")=-100%,"",IFERROR('Daily SY'!G4/MAX('Daily SY'!G$3:G$14)-1,"")) | G4: =IF(IFERROR('Daily SY'!H4/MAX('Daily SY'!H$3:H$14)-1,"")=-100%,"",IFERROR('Daily SY'!H4/MAX('Daily SY'!H$3:H$14)-1,"")) | H4: =IF(IFERROR('Daily SY'!I4/MAX('Daily SY'!I$3:I$18)-1,"")=-100%,"",IFERROR('Daily SY'!I4/MAX('Daily SY'!I$3:I$18)-1,"")) | I4: =IF(IFERROR('Daily SY'!J4/MAX('Daily SY'!J$3:J$14)-1,"")=-100%,"",IFERROR('Daily SY'!J4/MAX('Daily SY'!J$3:J$14)-1,"")) | J4: =IF(IFERROR('Daily SY'!K4/MAX('Daily SY'!K$3:K$14)-1,"")=-100%,"",IFERROR('Daily SY'!K4/MAX('Daily SY'!K$3:K$14)-1,"")) | K4: =IF(IFERROR('Daily SY'!L4/MAX('Daily SY'!L$3:L$14)-1,"")=-100%,"",IFERROR('Daily SY'!L4/MAX('Daily SY'!L$3:L$14)-1,"")) | L4: =IF(IFERROR('Daily SY'!M4/MAX('Daily SY'!M$3:M$14)-1,"")=-100%,"",IFERROR('Daily SY'!M4/MAX('Daily SY'!M$3:M$14)-1,"")) | M4: =IF(IFERROR('Daily SY'!N4/MAX('Daily SY'!N$3:N$14)-1,"")=-100%,"",IFERROR('Daily SY'!N4/MAX('Daily SY'!N$3:N$14)-1,"")) | N4: =IF(IFERROR('Daily SY'!O4/MAX('Daily SY'!O$3:O$14)-1,"")=-100%,"",IFERROR('Daily SY'!O4/MAX('Daily SY'!O$3:O$14)-1,"")) | O4: =IF(IFERROR('Daily SY'!P4/MAX('Daily SY'!P$3:P$14)-1,"")=-100%,"",IFERROR('Daily SY'!P4/MAX('Daily SY'!P$3:P$14)-1,"")) | P4: =IF(IFERROR('Daily SY'!Q4/MAX('Daily SY'!Q$3:Q$14)-1,"")=-100%,"",IFERROR('Daily SY'!Q4/MAX('Daily SY'!Q$3:Q$14)-1,"")) -> -0.046153846 | ... AF4: =IF(IFERROR('Daily SY'!AG4/MAX('Daily SY'!AG$3:AG$14)-1,"")=-100%,"",IFERROR('Daily SY'!AG4/MAX('Daily SY'!AG$3:AG$14)-1,""))
A5: INV-3 | B5: =IF(IFERROR('Daily SY'!C5/MAX('Daily SY'!C$3:C$14)-1,"")=-100%,"",IFERROR('Daily SY'!C5/MAX('Daily SY'!C$3:C$14)-1,"")) -> -0.061797753 | C5: =IF(IFERROR('Daily SY'!D5/MAX('Daily SY'!D$3:D$14)-1,"")=-100%,"",IFERROR('Daily SY'!D5/MAX('Daily SY'!D$3:D$14)-1,"")) | D5: =IF(IFERROR('Daily SY'!E5/MAX('Daily SY'!E$3:E$14)-1,"")=-100%,"",IFERROR('Daily SY'!E5/MAX('Daily SY'!E$3:E$14)-1,"")) | E5: =IF(IFERROR('Daily SY'!F5/MAX('Daily SY'!F$3:F$14)-1,"")=-100%,"",IFERROR('Daily SY'!F5/MAX('Daily SY'!F$3:F$14)-1,"")) | F5: =IF(IFERROR('Daily SY'!G5/MAX('Daily SY'!G$3:G$14)-1,"")=-100%,"",IFERROR('Daily SY'!G5/MAX('Daily SY'!G$3:G$14)-1,"")) | G5: =IF(IFERROR('Daily SY'!H5/MAX('Daily SY'!H$3:H$14)-1,"")=-100%,"",IFERROR('Daily SY'!H5/MAX('Daily SY'!H$3:H$14)-1,"")) | H5: =IF(IFERROR('Daily SY'!I5/MAX('Daily SY'!I$3:I$18)-1,"")=-100%,"",IFERROR('Daily SY'!I5/MAX('Daily SY'!I$3:I$18)-1,"")) | I5: =IF(IFERROR('Daily SY'!J5/MAX('Daily SY'!J$3:J$14)-1,"")=-100%,"",IFERROR('Daily SY'!J5/MAX('Daily SY'!J$3:J$14)-1,"")) | J5: =IF(IFERROR('Daily SY'!K5/MAX('Daily SY'!K$3:K$14)-1,"")=-100%,"",IFERROR('Daily SY'!K5/MAX('Daily SY'!K$3:K$14)-1,"")) | K5: =IF(IFERROR('Daily SY'!L5/MAX('Daily SY'!L$3:L$14)-1,"")=-100%,"",IFERROR('Daily SY'!L5/MAX('Daily SY'!L$3:L$14)-1,"")) | L5: =IF(IFERROR('Daily SY'!M5/MAX('Daily SY'!M$3:M$14)-1,"")=-100%,"",IFERROR('Daily SY'!M5/MAX('Daily SY'!M$3:M$14)-1,"")) | M5: =IF(IFERROR('Daily SY'!N5/MAX('Daily SY'!N$3:N$14)-1,"")=-100%,"",IFERROR('Daily SY'!N5/MAX('Daily SY'!N$3:N$14)-1,"")) | N5: =IF(IFERROR('Daily SY'!O5/MAX('Daily SY'!O$3:O$14)-1,"")=-100%,"",IFERROR('Daily SY'!O5/MAX('Daily SY'!O$3:O$14)-1,"")) | O5: =IF(IFERROR('Daily SY'!P5/MAX('Daily SY'!P$3:P$14)-1,"")=-100%,"",IFERROR('Daily SY'!P5/MAX('Daily SY'!P$3:P$14)-1,"")) | P5: =IF(IFERROR('Daily SY'!Q5/MAX('Daily SY'!Q$3:Q$14)-1,"")=-100%,"",IFERROR('Daily SY'!Q5/MAX('Daily SY'!Q$3:Q$14)-1,"")) -> -0.015384615 | ... AF5: =IF(IFERROR('Daily SY'!AG5/MAX('Daily SY'!AG$3:AG$14)-1,"")=-100%,"",IFERROR('Daily SY'!AG5/MAX('Daily SY'!AG$3:AG$14)-1,""))
A6: INV-4 | B6: =IF(IFERROR('Daily SY'!C6/MAX('Daily SY'!C$3:C$14)-1,"")=-100%,"",IFERROR('Daily SY'!C6/MAX('Daily SY'!C$3:C$14)-1,"")) -> -0.10674157 | C6: =IF(IFERROR('Daily SY'!D6/MAX('Daily SY'!D$3:D$14)-1,"")=-100%,"",IFERROR('Daily SY'!D6/MAX('Daily SY'!D$3:D$14)-1,"")) | D6: =IF(IFERROR('Daily SY'!E6/MAX('Daily SY'!E$3:E$14)-1,"")=-100%,"",IFERROR('Daily SY'!E6/MAX('Daily SY'!E$3:E$14)-1,"")) | E6: =IF(IFERROR('Daily SY'!F6/MAX('Daily SY'!F$3:F$14)-1,"")=-100%,"",IFERROR('Daily SY'!F6/MAX('Daily SY'!F$3:F$14)-1,"")) | F6: =IF(IFERROR('Daily SY'!G6/MAX('Daily SY'!G$3:G$14)-1,"")=-100%,"",IFERROR('Daily SY'!G6/MAX('Daily SY'!G$3:G$14)-1,"")) | G6: =IF(IFERROR('Daily SY'!H6/MAX('Daily SY'!H$3:H$14)-1,"")=-100%,"",IFERROR('Daily SY'!H6/MAX('Daily SY'!H$3:H$14)-1,"")) | H6: =IF(IFERROR('Daily SY'!I6/MAX('Daily SY'!I$3:I$18)-1,"")=-100%,"",IFERROR('Daily SY'!I6/MAX('Daily SY'!I$3:I$18)-1,"")) | I6: =IF(IFERROR('Daily SY'!J6/MAX('Daily SY'!J$3:J$14)-1,"")=-100%,"",IFERROR('Daily SY'!J6/MAX('Daily SY'!J$3:J$14)-1,"")) | J6: =IF(IFERROR('Daily SY'!K6/MAX('Daily SY'!K$3:K$14)-1,"")=-100%,"",IFERROR('Daily SY'!K6/MAX('Daily SY'!K$3:K$14)-1,"")) | K6: =IF(IFERROR('Daily SY'!L6/MAX('Daily SY'!L$3:L$14)-1,"")=-100%,"",IFERROR('Daily SY'!L6/MAX('Daily SY'!L$3:L$14)-1,"")) | L6: =IF(IFERROR('Daily SY'!M6/MAX('Daily SY'!M$3:M$14)-1,"")=-100%,"",IFERROR('Daily SY'!M6/MAX('Daily SY'!M$3:M$14)-1,"")) | M6: =IF(IFERROR('Daily SY'!N6/MAX('Daily SY'!N$3:N$14)-1,"")=-100%,"",IFERROR('Daily SY'!N6/MAX('Daily SY'!N$3:N$14)-1,"")) | N6: =IF(IFERROR('Daily SY'!O6/MAX('Daily SY'!O$3:O$14)-1,"")=-100%,"",IFERROR('Daily SY'!O6/MAX('Daily SY'!O$3:O$14)-1,"")) | O6: =IF(IFERROR('Daily SY'!P6/MAX('Daily SY'!P$3:P$14)-1,"")=-100%,"",IFERROR('Daily SY'!P6/MAX('Daily SY'!P$3:P$14)-1,"")) | P6: =IF(IFERROR('Daily SY'!Q6/MAX('Daily SY'!Q$3:Q$14)-1,"")=-100%,"",IFERROR('Daily SY'!Q6/MAX('Daily SY'!Q$3:Q$14)-1,"")) -> -0.096153846 | ... AF6: =IF(IFERROR('Daily SY'!AG6/MAX('Daily SY'!AG$3:AG$14)-1,"")=-100%,"",IFERROR('Daily SY'!AG6/MAX('Daily SY'!AG$3:AG$14)-1,""))
A7: INV-5 | B7: =IF(IFERROR('Daily SY'!C7/MAX('Daily SY'!C$3:C$14)-1,"")=-100%,"",IFERROR('Daily SY'!C7/MAX('Daily SY'!C$3:C$14)-1,"")) -> -0.16479401 | C7: =IF(IFERROR('Daily SY'!D7/MAX('Daily SY'!D$3:D$14)-1,"")=-100%,"",IFERROR('Daily SY'!D7/MAX('Daily SY'!D$3:D$14)-1,"")) | D7: =IF(IFERROR('Daily SY'!E7/MAX('Daily SY'!E$3:E$14)-1,"")=-100%,"",IFERROR('Daily SY'!E7/MAX('Daily SY'!E$3:E$14)-1,"")) | E7: =IF(IFERROR('Daily SY'!F7/MAX('Daily SY'!F$3:F$14)-1,"")=-100%,"",IFERROR('Daily SY'!F7/MAX('Daily SY'!F$3:F$14)-1,"")) | F7: =IF(IFERROR('Daily SY'!G7/MAX('Daily SY'!G$3:G$14)-1,"")=-100%,"",IFERROR('Daily SY'!G7/MAX('Daily SY'!G$3:G$14)-1,"")) | G7: =IF(IFERROR('Daily SY'!H7/MAX('Daily SY'!H$3:H$14)-1,"")=-100%,"",IFERROR('Daily SY'!H7/MAX('Daily SY'!H$3:H$14)-1,"")) | H7: =IF(IFERROR('Daily SY'!I7/MAX('Daily SY'!I$3:I$18)-1,"")=-100%,"",IFERROR('Daily SY'!I7/MAX('Daily SY'!I$3:I$18)-1,"")) | I7: =IF(IFERROR('Daily SY'!J7/MAX('Daily SY'!J$3:J$14)-1,"")=-100%,"",IFERROR('Daily SY'!J7/MAX('Daily SY'!J$3:J$14)-1,"")) | J7: =IF(IFERROR('Daily SY'!K7/MAX('Daily SY'!K$3:K$14)-1,"")=-100%,"",IFERROR('Daily SY'!K7/MAX('Daily SY'!K$3:K$14)-1,"")) | K7: =IF(IFERROR('Daily SY'!L7/MAX('Daily SY'!L$3:L$14)-1,"")=-100%,"",IFERROR('Daily SY'!L7/MAX('Daily SY'!L$3:L$14)-1,"")) | L7: =IF(IFERROR('Daily SY'!M7/MAX('Daily SY'!M$3:M$14)-1,"")=-100%,"",IFERROR('Daily SY'!M7/MAX('Daily SY'!M$3:M$14)-1,"")) | M7: =IF(IFERROR('Daily SY'!N7/MAX('Daily SY'!N$3:N$14)-1,"")=-100%,"",IFERROR('Daily SY'!N7/MAX('Daily SY'!N$3:N$14)-1,"")) | N7: =IF(IFERROR('Daily SY'!O7/MAX('Daily SY'!O$3:O$14)-1,"")=-100%,"",IFERROR('Daily SY'!O7/MAX('Daily SY'!O$3:O$14)-1,"")) | O7: =IF(IFERROR('Daily SY'!P7/MAX('Daily SY'!P$3:P$14)-1,"")=-100%,"",IFERROR('Daily SY'!P7/MAX('Daily SY'!P$3:P$14)-1,"")) | P7: =IF(IFERROR('Daily SY'!Q7/MAX('Daily SY'!Q$3:Q$14)-1,"")=-100%,"",IFERROR('Daily SY'!Q7/MAX('Daily SY'!Q$3:Q$14)-1,"")) -> -0.011538462 | ... AF7: =IF(IFERROR('Daily SY'!AG7/MAX('Daily SY'!AG$3:AG$14)-1,"")=-100%,"",IFERROR('Daily SY'!AG7/MAX('Daily SY'!AG$3:AG$14)-1,""))
A8: INV-6 | B8: =IF(IFERROR('Daily SY'!C8/MAX('Daily SY'!C$3:C$14)-1,"")=-100%,"",IFERROR('Daily SY'!C8/MAX('Daily SY'!C$3:C$14)-1,"")) -> -0.08988764 | C8: =IF(IFERROR('Daily SY'!D8/MAX('Daily SY'!D$3:D$14)-1,"")=-100%,"",IFERROR('Daily SY'!D8/MAX('Daily SY'!D$3:D$14)-1,"")) | D8: =IF(IFERROR('Daily SY'!E8/MAX('Daily SY'!E$3:E$14)-1,"")=-100%,"",IFERROR('Daily SY'!E8/MAX('Daily SY'!E$3:E$14)-1,"")) | E8: =IF(IFERROR('Daily SY'!F8/MAX('Daily SY'!F$3:F$14)-1,"")=-100%,"",IFERROR('Daily SY'!F8/MAX('Daily SY'!F$3:F$14)-1,"")) | F8: =IF(IFERROR('Daily SY'!G8/MAX('Daily SY'!G$3:G$14)-1,"")=-100%,"",IFERROR('Daily SY'!G8/MAX('Daily SY'!G$3:G$14)-1,"")) | G8: =IF(IFERROR('Daily SY'!H8/MAX('Daily SY'!H$3:H$14)-1,"")=-100%,"",IFERROR('Daily SY'!H8/MAX('Daily SY'!H$3:H$14)-1,"")) | H8: =IF(IFERROR('Daily SY'!I8/MAX('Daily SY'!I$3:I$18)-1,"")=-100%,"",IFERROR('Daily SY'!I8/MAX('Daily SY'!I$3:I$18)-1,"")) | I8: =IF(IFERROR('Daily SY'!J8/MAX('Daily SY'!J$3:J$14)-1,"")=-100%,"",IFERROR('Daily SY'!J8/MAX('Daily SY'!J$3:J$14)-1,"")) | J8: =IF(IFERROR('Daily SY'!K8/MAX('Daily SY'!K$3:K$14)-1,"")=-100%,"",IFERROR('Daily SY'!K8/MAX('Daily SY'!K$3:K$14)-1,"")) | K8: =IF(IFERROR('Daily SY'!L8/MAX('Daily SY'!L$3:L$14)-1,"")=-100%,"",IFERROR('Daily SY'!L8/MAX('Daily SY'!L$3:L$14)-1,"")) | L8: =IF(IFERROR('Daily SY'!M8/MAX('Daily SY'!M$3:M$14)-1,"")=-100%,"",IFERROR('Daily SY'!M8/MAX('Daily SY'!M$3:M$14)-1,"")) | M8: =IF(IFERROR('Daily SY'!N8/MAX('Daily SY'!N$3:N$14)-1,"")=-100%,"",IFERROR('Daily SY'!N8/MAX('Daily SY'!N$3:N$14)-1,"")) | N8: =IF(IFERROR('Daily SY'!O8/MAX('Daily SY'!O$3:O$14)-1,"")=-100%,"",IFERROR('Daily SY'!O8/MAX('Daily SY'!O$3:O$14)-1,"")) | O8: =IF(IFERROR('Daily SY'!P8/MAX('Daily SY'!P$3:P$14)-1,"")=-100%,"",IFERROR('Daily SY'!P8/MAX('Daily SY'!P$3:P$14)-1,"")) | P8: =IF(IFERROR('Daily SY'!Q8/MAX('Daily SY'!Q$3:Q$14)-1,"")=-100%,"",IFERROR('Daily SY'!Q8/MAX('Daily SY'!Q$3:Q$14)-1,"")) -> -0.061538462 | ... AF8: =IF(IFERROR('Daily SY'!AG8/MAX('Daily SY'!AG$3:AG$14)-1,"")=-100%,"",IFERROR('Daily SY'!AG8/MAX('Daily SY'!AG$3:AG$14)-1,""))
A9: INV-7 | B9: =IF(IFERROR('Daily SY'!C9/MAX('Daily SY'!C$3:C$14)-1,"")=-100%,"",IFERROR('Daily SY'!C9/MAX('Daily SY'!C$3:C$14)-1,"")) -> -0.033707865 | C9: =IF(IFERROR('Daily SY'!D9/MAX('Daily SY'!D$3:D$14)-1,"")=-100%,"",IFERROR('Daily SY'!D9/MAX('Daily SY'!D$3:D$14)-1,"")) | D9: =IF(IFERROR('Daily SY'!E9/MAX('Daily SY'!E$3:E$14)-1,"")=-100%,"",IFERROR('Daily SY'!E9/MAX('Daily SY'!E$3:E$14)-1,"")) | E9: =IF(IFERROR('Daily SY'!F9/MAX('Daily SY'!F$3:F$14)-1,"")=-100%,"",IFERROR('Daily SY'!F9/MAX('Daily SY'!F$3:F$14)-1,"")) | F9: =IF(IFERROR('Daily SY'!G9/MAX('Daily SY'!G$3:G$14)-1,"")=-100%,"",IFERROR('Daily SY'!G9/MAX('Daily SY'!G$3:G$14)-1,"")) | G9: =IF(IFERROR('Daily SY'!H9/MAX('Daily SY'!H$3:H$14)-1,"")=-100%,"",IFERROR('Daily SY'!H9/MAX('Daily SY'!H$3:H$14)-1,"")) | H9: =IF(IFERROR('Daily SY'!I9/MAX('Daily SY'!I$3:I$18)-1,"")=-100%,"",IFERROR('Daily SY'!I9/MAX('Daily SY'!I$3:I$18)-1,"")) | I9: =IF(IFERROR('Daily SY'!J9/MAX('Daily SY'!J$3:J$14)-1,"")=-100%,"",IFERROR('Daily SY'!J9/MAX('Daily SY'!J$3:J$14)-1,"")) | J9: =IF(IFERROR('Daily SY'!K9/MAX('Daily SY'!K$3:K$14)-1,"")=-100%,"",IFERROR('Daily SY'!K9/MAX('Daily SY'!K$3:K$14)-1,"")) | K9: =IF(IFERROR('Daily SY'!L9/MAX('Daily SY'!L$3:L$14)-1,"")=-100%,"",IFERROR('Daily SY'!L9/MAX('Daily SY'!L$3:L$14)-1,"")) | L9: =IF(IFERROR('Daily SY'!M9/MAX('Daily SY'!M$3:M$14)-1,"")=-100%,"",IFERROR('Daily SY'!M9/MAX('Daily SY'!M$3:M$14)-1,"")) | M9: =IF(IFERROR('Daily SY'!N9/MAX('Daily SY'!N$3:N$14)-1,"")=-100%,"",IFERROR('Daily SY'!N9/MAX('Daily SY'!N$3:N$14)-1,"")) | N9: =IF(IFERROR('Daily SY'!O9/MAX('Daily SY'!O$3:O$14)-1,"")=-100%,"",IFERROR('Daily SY'!O9/MAX('Daily SY'!O$3:O$14)-1,"")) | O9: =IF(IFERROR('Daily SY'!P9/MAX('Daily SY'!P$3:P$14)-1,"")=-100%,"",IFERROR('Daily SY'!P9/MAX('Daily SY'!P$3:P$14)-1,"")) | P9: =IF(IFERROR('Daily SY'!Q9/MAX('Daily SY'!Q$3:Q$14)-1,"")=-100%,"",IFERROR('Daily SY'!Q9/MAX('Daily SY'!Q$3:Q$14)-1,"")) -> -0.071428571 | ... AF9: =IF(IFERROR('Daily SY'!AG9/MAX('Daily SY'!AG$3:AG$14)-1,"")=-100%,"",IFERROR('Daily SY'!AG9/MAX('Daily SY'!AG$3:AG$14)-1,""))
